<?xml version="1.0" encoding="UTF-8"?>
<testng-results ignored="0" total="1" passed="0" failed="1" skipped="0">
  <reporter-output>
  </reporter-output>
  <suite started-at="2022-05-02T15:41:27 EDT" name="Failed suite [Default suite]" finished-at="2022-05-02T15:41:28 EDT" duration-ms="500">
    <groups>
    </groups>
    <test started-at="2022-05-02T15:41:27 EDT" name="Default test(failed)" finished-at="2022-05-02T15:41:28 EDT" duration-ms="500">
      <class name="testcases.LoginTest">
        <test-method is-config="true" signature="init()[pri:0, instance:testcases.LoginTest@7f552bd3]" started-at="2022-05-02T15:41:27 EDT" name="init" finished-at="2022-05-02T15:41:28 EDT" duration-ms="165" status="PASS">
          <reporter-output>
          </reporter-output>
        </test-method> <!-- init -->
        <test-method signature="login()[pri:0, instance:testcases.LoginTest@7f552bd3]" started-at="2022-05-02T15:41:28 EDT" name="login" finished-at="2022-05-02T15:41:28 EDT" duration-ms="9" status="FAIL">
          <exception class="java.lang.AssertionError">
            <message>
              <![CDATA[404 Error]]>
            </message>
            <full-stacktrace>
              <![CDATA[java.lang.AssertionError: 404 Error
at org.testng.Assert.fail(Assert.java:97)
at testcases.LoginTest.login(LoginTest.java:77)
at java.base/jdk.internal.reflect.DirectMethodHandleAccessor.invoke(DirectMethodHandleAccessor.java:104)
at java.base/java.lang.reflect.Method.invoke(Method.java:577)
at org.testng.internal.MethodInvocationHelper.invokeMethod(MethodInvocationHelper.java:133)
at org.testng.internal.TestInvoker.invokeMethod(TestInvoker.java:584)
at org.testng.internal.TestInvoker.invokeTestMethod(TestInvoker.java:172)
at org.testng.internal.MethodRunner.runInSequence(MethodRunner.java:46)
at org.testng.internal.TestInvoker$MethodInvocationAgent.invoke(TestInvoker.java:804)
at org.testng.internal.TestInvoker.invokeTestMethods(TestInvoker.java:145)
at org.testng.internal.TestMethodWorker.invokeTestMethods(TestMethodWorker.java:146)
at org.testng.internal.TestMethodWorker.run(TestMethodWorker.java:128)
at java.base/java.util.ArrayList.forEach(ArrayList.java:1511)
at org.testng.TestRunner.privateRun(TestRunner.java:770)
at org.testng.TestRunner.run(TestRunner.java:591)
at org.testng.SuiteRunner.runTest(SuiteRunner.java:402)
at org.testng.SuiteRunner.runSequentially(SuiteRunner.java:396)
at org.testng.SuiteRunner.privateRun(SuiteRunner.java:355)
at org.testng.SuiteRunner.run(SuiteRunner.java:304)
at org.testng.SuiteRunnerWorker.runSuite(SuiteRunnerWorker.java:53)
at org.testng.SuiteRunnerWorker.run(SuiteRunnerWorker.java:96)
at org.testng.TestNG.runSuitesSequentially(TestNG.java:1180)
at org.testng.TestNG.runSuitesLocally(TestNG.java:1102)
at org.testng.TestNG.runSuites(TestNG.java:1032)
at org.testng.TestNG.run(TestNG.java:1000)
at org.testng.remote.AbstractRemoteTestNG.run(AbstractRemoteTestNG.java:115)
at org.testng.remote.RemoteTestNG.initAndRun(RemoteTestNG.java:251)
at org.testng.remote.RemoteTestNG.main(RemoteTestNG.java:77)
]]>
            </full-stacktrace>
          </exception> <!-- java.lang.AssertionError -->
          <reporter-output>
          </reporter-output>
        </test-method> <!-- login -->
        <test-method is-config="true" signature="quit()[pri:0, instance:testcases.LoginTest@7f552bd3]" started-at="2022-05-02T15:41:28 EDT" name="quit" finished-at="2022-05-02T15:41:28 EDT" duration-ms="294" status="PASS">
          <reporter-output>
          </reporter-output>
        </test-method> <!-- quit -->
      </class> <!-- testcases.LoginTest -->
    </test> <!-- Default test(failed) -->
  </suite> <!-- Failed suite [Default suite] -->
</testng-results>
